<mujocoinclude model="MyoArm_v0.2">
    <!-- <light pos="0 0 1.5" dir="0 0 -1" directional="true"/>
    <geom type="plane" size="3 3 .01" material="grid" pos = "0 0 -1"/> -->
    <!-- <geom type="sphere" size="0.05" rgba="1 0 0 1" pos="0 0 0"/> -->
    <body name="static" pos = "0 0 0.89 " quat="0 0 0.7071 0.7071">
        <!-- <joint type="free"/> -->
        <geom mesh="frame" material="metal" conaffinity="0" contype="0"/>
        <geom mesh="armrest1" material="orange"/>
        <geom mesh="armrest2" material="orange"/>
        <geom mesh="backrest" material="dark_blue"/>
        <geom mesh="footplate1" material="grey"/>
        <geom mesh="footplate2" material="grey"/>
        <geom mesh="push_handle1" material="cyan"/>
        <geom mesh="push_handle2" material="cyan"/>
        <geom mesh="seat" material="dark_blue"/>
        <geom mesh="side_panel1" material="metal"/>
        <geom mesh="side_panel2" material="metal"/>
        
        <body name = "right_rear_wheel" pos="-0.0635 -0.5842 -0.1524">
            <joint name= "right_rear" axis="-1 0 0" damping=".03"/>
            <geom mesh= "rear_wheel1" pos="0.0635 0.5842 0.1524" material="dark_grey" conaffinity="0" contype="0"/>
            <geom name = "right_rear_coll" type="cylinder" size="0.3048" fromto="-0.0127 0 0 0.0127 0 0" rgba="1 0 0 0"/>
            <geom name = "right_handrail_coll" type="cylinder" pos = "-0.038 0 0" size="0.2762 0.0082" euler="0 1.5708 0" rgba="0 0 1 0"/>
        </body>
        <body name = "left_rear_wheel" pos="0.4953 -0.5842 -0.1524">
            <joint name= "left_rear" axis="-1 0 0" damping=".03"/>
            <geom mesh= "rear_wheel2" pos="-0.4953 0.5842 0.1524" material="dark_grey" conaffinity="0" contype="0"/>
            <geom name = "left_rear_coll" type="cylinder" size="0.3048" fromto="-0.0127 0 0 0.0127 0 0" rgba="1 0 0 0"/>
            <geom name = "left_handrail_coll" type="cylinder" pos = "0.038 0 0" size="0.2762 0.0082" euler="0 1.5708 0" rgba="0 0 1 0"/>
        </body>
        
        <body name = "right_fork" pos="0 -0.78105 -0.607055">
            <joint name= "right_fork" axis="0 -1 0" damping=".03" limited="true" range="-60 60"/>
            <geom mesh= "caster_fork1" pos="0 0.78105 0.607055" material="metal"/>
            <geom mesh= "pin1" pos="0 0.78105 0.607055" material="metal"/>
                
            <body name = "right_caster_wheel" pos="0 0 -0.049375">
                <joint name= "right_caster" axis="-1 0 0" damping=".03"/>
                <geom mesh= "caster_wheel1" pos="0 0.78105 0.65643" material="dark_grey"/>
            </body>
            
        </body>
        <body name = "left_fork" pos="0.4318 -0.78105 -0.60563">
            <joint name= "left_fork" axis="0 -1 0" damping=".03" limited="true" range="-60 60"/>
            <geom mesh= "caster_fork2" pos="-0.4318 0.78105 0.60563" material="metal"/>
            <geom mesh= "pin2" pos="-0.4318 0.78105 0.60563" material="metal"/>
            
            <body name = "left_caster_wheel" pos="0 0 -0.0508">
                <joint name= "left_caster" axis="-1 0 0" damping=".03"/>
                <geom mesh= "caster_wheel2" pos="-0.4318 0.78105 0.65643" material="dark_grey"/>
            </body> 
            
        </body>
    </body>
</mujocoinclude>