<mujocoinclude model="MyoArm_v0.01">
<body name="wheelchair" pos="0 0 0.89" quat="0 0 0.7071 0.7071">
    <geom mesh="frame" material="metal"/>
    <geom mesh="armrest1" material="orange"/>
    <geom mesh="armrest2" material="orange"/>
    <geom mesh="backrest" material="dark_blue"/>
    <geom mesh="footplate1" material="grey"/>
    <geom mesh="footplate2" material="grey"/>
    <geom mesh="push_handle1" material="cyan"/>
    <geom mesh="push_handle2" material="cyan"/>
    <geom mesh="seat" material="dark_blue"/>
    <geom mesh="side_panel1" material="metal"/>
    <geom mesh="side_panel2" material="metal"/>

    <body name="right_fork" pos="0 -0.78105 -0.607055">
        <joint name="right_fork" axis="0 -1 0" damping=".03" limited="true" range="-60 60"/>
        <geom mesh="caster_fork1" pos="0 0.78105 0.607055" material="metal"/>
        <geom mesh="pin1" pos="0 0.78105 0.607055" material="metal"/>
    </body>

    <body name="left_fork" pos="0.4318 -0.78105 -0.60563">
        <joint name="left_fork" axis="0 -1 0" damping=".03" limited="true" range="-60 60"/>
        <geom mesh="caster_fork2" pos="-0.4318 0.78105 0.60563" material="metal"/>
        <geom mesh="pin2" pos="-0.4318 0.78105 0.60563" material="metal"/>
    </body>
</body>
</mujocoinclude>